{
  "dataType": "CVE_RECORD",
  "dataVersion": "5.0",
  "cveMetadata": {
    "assignerOrgId": "a0819718-46f1-4df5-94e2-005712e83aaa",
    "assignerShortName": "GitHub_M",
    "cveId": "CVE-2022-41893",
    "datePublished": "2022-11-18T00:00:00",
    "dateReserved": "2022-09-30T00:00:00",
    "dateUpdated": "2022-11-18T00:00:00",
    "state": "PUBLISHED"
  },
  "containers": {
    "cna": {
      "affected": [
        {
          "product": "tensorflow",
          "vendor": "tensorflow",
          "versions": [
            {
              "status": "affected",
              "version": ">= 2.10.0, < 2.10.1"
            },
            {
              "status": "affected",
              "version": ">= 2.9.0, < 2.9.3"
            },
            {
              "status": "affected",
              "version": "< 2.8.4"
            }
          ]
        }
      ],
      "descriptions": [
        {
          "lang": "en",
          "value": "TensorFlow is an open source platform for machine learning. If `tf.raw_ops.TensorListResize` is given a nonscalar value for input `size`, it results `CHECK` fail which can be used to trigger a denial of service attack. We have patched the issue in GitHub commit 888e34b49009a4e734c27ab0c43b0b5102682c56. The fix will be included in TensorFlow 2.11. We will also cherrypick this commit on TensorFlow 2.10.1, 2.9.3, and TensorFlow 2.8.4, as these are also affected and still in supported range."
        }
      ],
      "metrics": [
        {
          "cvssV3_1": {
            "version": "3.1",
            "vectorString": "CVSS:3.1/AV:N/AC:H/PR:L/UI:R/S:U/C:N/I:N/A:H",
            "baseScore": 4.8,
            "baseSeverity": "MEDIUM",
            "attackComplexity": "HIGH",
            "attackVector": "NETWORK",
            "availabilityImpact": "HIGH",
            "confidentialityImpact": "NONE",
            "integrityImpact": "NONE",
            "privilegesRequired": "LOW",
            "scope": "UNCHANGED",
            "userInteraction": "REQUIRED"
          }
        }
      ],
      "problemTypes": [
        {
          "descriptions": [
            {
              "cweid": "CWE-617",
              "description": "CWE-617: Reachable Assertion",
              "lang": "en",
              "type": "CWE"
            }
          ]
        }
      ],
      "providerMetadata": {
        "dateUpdated": "2022-11-18T00:00:00",
        "orgId": "a0819718-46f1-4df5-94e2-005712e83aaa",
        "shortName": "GitHub_M"
      },
      "references": [
        {
          "url": "https://github.com/tensorflow/tensorflow/security/advisories/GHSA-67pf-62xr-q35m"
        },
        {
          "url": "https://github.com/tensorflow/tensorflow/commit/888e34b49009a4e734c27ab0c43b0b5102682c56"
        },
        {
          "url": "https://github.com/tensorflow/tensorflow/blob/master/tensorflow/core/kernels/list_kernels.cc"
        }
      ],
      "source": {
        "advisory": "GHSA-67pf-62xr-q35m",
        "discovery": "UNKNOWN"
      },
      "title": "`CHECK_EQ` fail in `tf.raw_ops.TensorListResize` in Tensorflow"
    }
  }
}
