{
	"dataType": "CVE_RECORD",
	"dataVersion": "5.1",
	"cveMetadata": {
		"cveId": "CVE-2022-47515",
		"assignerOrgId": "8254265b-2729-46b6-b9e3-3dfca2d5bfca",
		"assignerShortName": "mitre",
		"state": "PUBLISHED",
		"datePublished": "2022-12-18T00:00:00",
		"dateUpdated": "2024-08-03T14:55:08.386Z",
		"dateReserved": "2022-12-18T00:00:00"
	},
	"containers": {
		"cna": {
			"providerMetadata": {
				"orgID": "8254265b-2729-46b6-b9e3-3dfca2d5bfca",
				"shortName": "mitre",
				"dateUpdated": "2022-12-18T00:00:00"
			},
			"descriptions": [
				{
					"lang": "en",
					"value": "An issue was discovered in drachtio-server before 0.8.20. It allows remote attackers to cause a denial of service (daemon crash) via a long message in a TCP request that leads to std::length_error."
				}
			],
			"affected": [
				{
					"vendor": "n/a",
					"product": "n/a",
					"versions": [
						{
							"status": "affected",
							"version": "n/a"
						}
					]
				}
			],
			"problemTypes": [
				{
					"descriptions": [
						{
							"type": "text",
							"lang": "en",
							"description": "n/a"
						}
					]
				}
			],
			"references": [
				{
					"url": "https://github.com/drachtio/drachtio-server/issues/245"
				},
				{
					"url": "https://github.com/drachtio/drachtio-server/commit/4cf9fe2c420b86c16442215d449d40be777c1911"
				}
			]
		},
		"adp": [
			{
				"providerMetadata": {
					"orgID": "af854a3a-2127-422b-91ae-364da2661108",
					"shortName": "CVE",
					"dateUpdated": "2024-08-03T14:55:08.386Z"
				},
				"title": "CVE Program Container",
				"references": [
					{
						"tags": [
							"x_transferred"
						],
						"url": "https://github.com/drachtio/drachtio-server/issues/245"
					},
					{
						"tags": [
							"x_transferred"
						],
						"url": "https://github.com/drachtio/drachtio-server/commit/4cf9fe2c420b86c16442215d449d40be777c1911"
					}
				]
			}
		]
	}
}
